<?xml version="1.0"?>
<robot name="three_DOF_robot">

<!-- Used for fixing robot to Gazebo 'base_link' -->
  <link name="world"/>

  <joint name="glue_robot_to_world" type="fixed">
    <parent link="world"/>
    <child link="link1"/>
  </joint>

<!-- All Robot Links -->
  <!-- Base Link -->
  <link name="link1">
    <collision>
      <origin xyz="0 0 0.5" rpy="0 0 0"/>
      <geometry>
       <box size="0.2 0.2 0.7"/>
      </geometry>
    </collision>

    <visual>
      <origin xyz="0 0 0.5" rpy="0 0 0"/>
      <geometry>
        <box size="0.2 0.2 1"/>
      </geometry>
    </visual>

    <inertial>
      <origin xyz="0 0 0.5" rpy="0 0 0"/>
      <mass value="1"/>
      <inertia
        ixx="1.0" ixy="0.0" ixz="0.0"
        iyy="1.0" iyz="0.0"
        izz="1.0"/>
    </inertial>
  </link>

  <!-- Moveable Link -->
  <link name="link2">
    <collision>
      <origin xyz="0 0 0.5" rpy="0 0 0"/>
      <geometry>
        <cylinder length="1" radius="0.1"/>
        <!--box size="0.15 0.15 0.8"-->
      </geometry>
    </collision>

    <visual>
      <origin xyz="0 0 0.5" rpy="0 0 0"/>
      <geometry>
        <cylinder length="1" radius="0.1"/>
      </geometry>
    </visual>

    <inertial>
      <origin xyz="0 0 0.5" rpy="0 0 0"/>
      <mass value="0.5"/>
      <inertia
        ixx="0.1" ixy="0.0" ixz="0.0"
        iyy="0.1" iyz="0.0"
        izz="0.005"/>
    </inertial>
  </link>

  <!-- Second Moveable Link -->
  <link name="link3">
    <collision>
      <origin xyz="0 0 0.5" rpy="0 0 0"/>
      <geometry>
        <cylinder length="1" radius="0.05"/>
        <!--box size="0.15 0.15 0.8"-->
      </geometry>
    </collision>

    <visual>
      <origin xyz="0 0 0.5" rpy="0 0 0"/>
      <geometry>
        <cylinder length="1" radius="0.05"/>
      </geometry>
    </visual>

    <inertial>
      <origin xyz="0 0 0.5" rpy="0 0 0"/>
      <mass value="0.25"/>
      <inertia
        ixx="0.1" ixy="0.0" ixz="0.0"
        iyy="0.1" iyz="0.0"
        izz="0.005"/>
    </inertial>
  </link>

  <!-- Third Moveable Link -->
  <link name="link4">
    <collision>
      <origin xyz="0 0 0.5" rpy="0 0 0"/>
      <geometry>
        <cylinder length="1" radius="0.025"/>
        <!--box size="0.15 0.15 0.8"-->
      </geometry>
    </collision>

    <visual>
      <origin xyz="0 0 0.5" rpy="0 0 0"/>
      <geometry>
        <cylinder length="1" radius="0.025"/>
      </geometry>
    </visual>

    <inertial>
      <origin xyz="0 0 0.5" rpy="0 0 0"/>
      <mass value="0.125"/>
      <inertia
        ixx="0.1" ixy="0.0" ixz="0.0"
        iyy="0.1" iyz="0.0"
        izz="0.005"/>
    </inertial>
  </link>


<!-- All Robot Joints -->
  <joint name="joint1" type="revolute">
    <parent link="link1"/>
    <child link="link2"/>
    <origin xyz="0 0 1" rpy="0 0 0"/>
    <axis xyz="1 0 0"/>
    <limit effort = "10.0" lower = "-1.1" upper = "1.1" velocity = "1.0"/>
    <dynamics damping = "1.0"/>
  </joint>

  <joint name="joint2" type="revolute">
    <parent link="link2"/>
    <child link="link3"/>
    <origin xyz="0 0 1" rpy="0 0 0"/>
    <axis xyz="0 1 0"/>
    <limit effort = "10.0" lower = "-1.1" upper = "1.1" velocity = "1.0"/>
    <dynamics damping = "1.0"/>
  </joint>

  <joint name="joint3" type="revolute">
    <parent link="link3"/>
    <child link="link4"/>
    <origin xyz="0 0 1" rpy="0 0 0"/>
    <axis xyz="1 0 0"/>
    <limit effort = "10.0" lower = "-1.1" upper = "1.1" velocity = "1.0"/>
    <dynamics damping = "1.0"/>
  </joint>


<!-- All Robot Transmissions -->
  <transmission name="tran1">
    <type>transmission_interface/SimpleTransmission</type>
    <joint name="joint1">
      <hardwareInterface>EffortJointInterface</hardwareInterface>
    </joint>
    <actuator name="motor1">
      <hardwareInterface>EffortJointInterface</hardwareInterface>
      <mechanicalReduction>1</mechanicalReduction>
    </actuator>
  </transmission>

  <transmission name="tran2">
    <type>transmission_interface/SimpleTransmission</type>
    <joint name="joint2">
      <hardwareInterface>EffortJointInterface</hardwareInterface>
    </joint>
    <actuator name="motor2">
      <hardwareInterface>EffortJointInterface</hardwareInterface>
      <mechanicalReduction>1</mechanicalReduction>
    </actuator>
  </transmission>

  <transmission name="tran3">
    <type>transmission_interface/SimpleTransmission</type>
    <joint name="joint3">
      <hardwareInterface>EffortJointInterface</hardwareInterface>
    </joint>
    <actuator name="motor3">
      <hardwareInterface>EffortJointInterface</hardwareInterface>
      <mechanicalReduction>1</mechanicalReduction>
    </actuator>
  </transmission>


<!-- Gazebo Instruction: Use ROS Controller -->
  <gazebo>
     <plugin name="gazebo_ros_control" filename="libgazebo_ros_control.so">
       <robotNamespace>/three_dof_robot</robotNamespace>
     </plugin>
  </gazebo>


</robot>
